Traceback (most recent call last):
  File "C:\Users\sandr\anaconda3\envs\renv\lib\site-packages\jupyter_cache\executors\utils.py", line 56, in single_nb_execution
    record_timing=False,
  File "C:\Users\sandr\anaconda3\envs\renv\lib\site-packages\nbclient\client.py", line 1204, in execute
    return NotebookClient(nb=nb, resources=resources, km=km, **kwargs).execute()
  File "C:\Users\sandr\anaconda3\envs\renv\lib\site-packages\nbclient\util.py", line 84, in wrapped
    return just_run(coro(*args, **kwargs))
  File "C:\Users\sandr\anaconda3\envs\renv\lib\site-packages\nbclient\util.py", line 62, in just_run
    return loop.run_until_complete(coro)
  File "C:\Users\sandr\anaconda3\envs\renv\lib\asyncio\base_events.py", line 587, in run_until_complete
    return future.result()
  File "C:\Users\sandr\anaconda3\envs\renv\lib\site-packages\nbclient\client.py", line 664, in async_execute
    cell, index, execution_count=self.code_cells_executed + 1
  File "C:\Users\sandr\anaconda3\envs\renv\lib\site-packages\nbclient\client.py", line 965, in async_execute_cell
    await self._check_raise_for_error(cell, cell_index, exec_reply)
  File "C:\Users\sandr\anaconda3\envs\renv\lib\site-packages\nbclient\client.py", line 862, in _check_raise_for_error
    raise CellExecutionError.from_cell_and_msg(cell, exec_reply_content)
nbclient.exceptions.CellExecutionError: An error occurred while executing the following cell:
------------------
from sklearn.tree import DecisionTreeRegressor
import graphviz
from sklearn import tree
from sklearn.tree import export_graphviz 
from sklearn.metrics import accuracy_score
from pandas import Series
from simple_colors import *
import statsmodels.api as sm
import statsmodels.formula.api as smf
from scipy.stats import norm
from sklearn.metrics import accuracy_score
from sklearn import metrics
from sklearn.metrics import r2_score
import matplotlib.pyplot as plt
from sklearn import tree
from sklearn.model_selection import train_test_split
------------------

[1;31m---------------------------------------------------------------------------[0m
[1;31mModuleNotFoundError[0m                       Traceback (most recent call last)
[1;32m~\AppData\Local\Temp/ipykernel_14752/2063672304.py[0m in [0;36m<module>[1;34m[0m
[0;32m      5[0m [1;32mfrom[0m [0msklearn[0m[1;33m.[0m[0mmetrics[0m [1;32mimport[0m [0maccuracy_score[0m[1;33m[0m[1;33m[0m[0m
[0;32m      6[0m [1;32mfrom[0m [0mpandas[0m [1;32mimport[0m [0mSeries[0m[1;33m[0m[1;33m[0m[0m
[1;32m----> 7[1;33m [1;32mfrom[0m [0msimple_colors[0m [1;32mimport[0m [1;33m*[0m[1;33m[0m[1;33m[0m[0m
[0m[0;32m      8[0m [1;32mimport[0m [0mstatsmodels[0m[1;33m.[0m[0mapi[0m [1;32mas[0m [0msm[0m[1;33m[0m[1;33m[0m[0m
[0;32m      9[0m [1;32mimport[0m [0mstatsmodels[0m[1;33m.[0m[0mformula[0m[1;33m.[0m[0mapi[0m [1;32mas[0m [0msmf[0m[1;33m[0m[1;33m[0m[0m

[1;31mModuleNotFoundError[0m: No module named 'simple_colors'
ModuleNotFoundError: No module named 'simple_colors'

