Traceback (most recent call last):
  File "C:\Users\sandr\anaconda3\envs\renv\lib\site-packages\jupyter_cache\executors\utils.py", line 56, in single_nb_execution
    record_timing=False,
  File "C:\Users\sandr\anaconda3\envs\renv\lib\site-packages\nbclient\client.py", line 1204, in execute
    return NotebookClient(nb=nb, resources=resources, km=km, **kwargs).execute()
  File "C:\Users\sandr\anaconda3\envs\renv\lib\site-packages\nbclient\util.py", line 84, in wrapped
    return just_run(coro(*args, **kwargs))
  File "C:\Users\sandr\anaconda3\envs\renv\lib\site-packages\nbclient\util.py", line 62, in just_run
    return loop.run_until_complete(coro)
  File "C:\Users\sandr\anaconda3\envs\renv\lib\asyncio\base_events.py", line 587, in run_until_complete
    return future.result()
  File "C:\Users\sandr\anaconda3\envs\renv\lib\site-packages\nbclient\client.py", line 664, in async_execute
    cell, index, execution_count=self.code_cells_executed + 1
  File "C:\Users\sandr\anaconda3\envs\renv\lib\site-packages\nbclient\client.py", line 965, in async_execute_cell
    await self._check_raise_for_error(cell, cell_index, exec_reply)
  File "C:\Users\sandr\anaconda3\envs\renv\lib\site-packages\nbclient\client.py", line 862, in _check_raise_for_error
    raise CellExecutionError.from_cell_and_msg(cell, exec_reply_content)
nbclient.exceptions.CellExecutionError: An error occurred while executing the following cell:
------------------
import random
import pandas as pd
import numpy as np
from scipy.stats import norm

import statsmodels.api as sm
import statsmodels.formula.api as smf
import patsy
from SyncRNG import SyncRNG
import numpy as np
import re
from statsmodels.sandbox.stats.multicomp import multipletests
from scipy import linalg
from itertools import chain

from SyncRNG import SyncRNG

from CTL.causal_tree_learn import CausalTree
from sklearn.model_selection import train_test_split
import plotnine as p
import seaborn as sns
import matplotlib.pyplot as plt
import matplotlib.patches as mpatches
------------------

[1;31m---------------------------------------------------------------------------[0m
[1;31mModuleNotFoundError[0m                       Traceback (most recent call last)
[1;32m~\AppData\Local\Temp/ipykernel_4196/2508031605.py[0m in [0;36m<module>[1;34m[0m
[0;32m     16[0m [1;32mfrom[0m [0mSyncRNG[0m [1;32mimport[0m [0mSyncRNG[0m[1;33m[0m[1;33m[0m[0m
[0;32m     17[0m [1;33m[0m[0m
[1;32m---> 18[1;33m [1;32mfrom[0m [0mCTL[0m[1;33m.[0m[0mcausal_tree_learn[0m [1;32mimport[0m [0mCausalTree[0m[1;33m[0m[1;33m[0m[0m
[0m[0;32m     19[0m [1;32mfrom[0m [0msklearn[0m[1;33m.[0m[0mmodel_selection[0m [1;32mimport[0m [0mtrain_test_split[0m[1;33m[0m[1;33m[0m[0m
[0;32m     20[0m [1;32mimport[0m [0mplotnine[0m [1;32mas[0m [0mp[0m[1;33m[0m[1;33m[0m[0m

[1;31mModuleNotFoundError[0m: No module named 'CTL'
ModuleNotFoundError: No module named 'CTL'

