Traceback (most recent call last):
  File "/opt/hostedtoolcache/Python/3.8.15/x64/lib/python3.8/site-packages/jupyter_cache/executors/utils.py", line 51, in single_nb_execution
    executenb(
  File "/opt/hostedtoolcache/Python/3.8.15/x64/lib/python3.8/site-packages/nbclient/client.py", line 1204, in execute
    return NotebookClient(nb=nb, resources=resources, km=km, **kwargs).execute()
  File "/opt/hostedtoolcache/Python/3.8.15/x64/lib/python3.8/site-packages/nbclient/util.py", line 84, in wrapped
    return just_run(coro(*args, **kwargs))
  File "/opt/hostedtoolcache/Python/3.8.15/x64/lib/python3.8/site-packages/nbclient/util.py", line 62, in just_run
    return loop.run_until_complete(coro)
  File "/opt/hostedtoolcache/Python/3.8.15/x64/lib/python3.8/asyncio/base_events.py", line 616, in run_until_complete
    return future.result()
  File "/opt/hostedtoolcache/Python/3.8.15/x64/lib/python3.8/site-packages/nbclient/client.py", line 663, in async_execute
    await self.async_execute_cell(
  File "/opt/hostedtoolcache/Python/3.8.15/x64/lib/python3.8/site-packages/nbclient/client.py", line 965, in async_execute_cell
    await self._check_raise_for_error(cell, cell_index, exec_reply)
  File "/opt/hostedtoolcache/Python/3.8.15/x64/lib/python3.8/site-packages/nbclient/client.py", line 862, in _check_raise_for_error
    raise CellExecutionError.from_cell_and_msg(cell, exec_reply_content)
nbclient.exceptions.CellExecutionError: An error occurred while executing the following cell:
------------------
#First we import the necesary packages to use in chapter 3 code
from scipy import stats
from scipy.stats import norm
import statsmodels.api as sm
import statsmodels.formula.api as smf
import patsy
import patsy
%matplotlib inline
import matplotlib
import matplotlib.mlab as mlab
import seaborn as sns
import random
import string
import warnings
warnings.filterwarnings('ignore')
import imageio as iio
import matplotlib.image as mpimg
import matplotlib.pyplot as plt
import requests
from urllib.request import urlopen
import imageio
import png
from PIL import Image
from io import BytesIO
------------------

[0;31m---------------------------------------------------------------------------[0m
[0;31mModuleNotFoundError[0m                       Traceback (most recent call last)
Cell [0;32mIn[14], line 22[0m
[1;32m     20[0m [38;5;28;01mfrom[39;00m [38;5;21;01murllib[39;00m[38;5;21;01m.[39;00m[38;5;21;01mrequest[39;00m [38;5;28;01mimport[39;00m urlopen
[1;32m     21[0m [38;5;28;01mimport[39;00m [38;5;21;01mimageio[39;00m
[0;32m---> 22[0m [38;5;28;01mimport[39;00m [38;5;21;01mpng[39;00m
[1;32m     23[0m [38;5;28;01mfrom[39;00m [38;5;21;01mPIL[39;00m [38;5;28;01mimport[39;00m Image
[1;32m     24[0m [38;5;28;01mfrom[39;00m [38;5;21;01mio[39;00m [38;5;28;01mimport[39;00m BytesIO

[0;31mModuleNotFoundError[0m: No module named 'png'
ModuleNotFoundError: No module named 'png'

