Traceback (most recent call last):
  File "/opt/hostedtoolcache/Python/3.8.14/x64/lib/python3.8/site-packages/jupyter_cache/executors/utils.py", line 51, in single_nb_execution
    executenb(
  File "/opt/hostedtoolcache/Python/3.8.14/x64/lib/python3.8/site-packages/nbclient/client.py", line 1204, in execute
    return NotebookClient(nb=nb, resources=resources, km=km, **kwargs).execute()
  File "/opt/hostedtoolcache/Python/3.8.14/x64/lib/python3.8/site-packages/nbclient/util.py", line 84, in wrapped
    return just_run(coro(*args, **kwargs))
  File "/opt/hostedtoolcache/Python/3.8.14/x64/lib/python3.8/site-packages/nbclient/util.py", line 62, in just_run
    return loop.run_until_complete(coro)
  File "/opt/hostedtoolcache/Python/3.8.14/x64/lib/python3.8/asyncio/base_events.py", line 616, in run_until_complete
    return future.result()
  File "/opt/hostedtoolcache/Python/3.8.14/x64/lib/python3.8/site-packages/nbclient/client.py", line 663, in async_execute
    await self.async_execute_cell(
  File "/opt/hostedtoolcache/Python/3.8.14/x64/lib/python3.8/site-packages/nbclient/client.py", line 965, in async_execute_cell
    await self._check_raise_for_error(cell, cell_index, exec_reply)
  File "/opt/hostedtoolcache/Python/3.8.14/x64/lib/python3.8/site-packages/nbclient/client.py", line 862, in _check_raise_for_error
    raise CellExecutionError.from_cell_and_msg(cell, exec_reply_content)
nbclient.exceptions.CellExecutionError: An error occurred while executing the following cell:
------------------
import random
import pandas as pd
import numpy as np
from scipy.stats import norm

import statsmodels.api as sm
import statsmodels.formula.api as smf
import patsy
from SyncRNG import SyncRNG
import numpy as np
import re
from statsmodels.sandbox.stats.multicomp import multipletests
from scipy import linalg
from itertools import chain

from SyncRNG import SyncRNG

from CTL.causal_tree_learn import CausalTree
from sklearn.model_selection import train_test_split
import plotnine as p
import seaborn as sns
import matplotlib.pyplot as plt
import matplotlib.patches as mpatches

import warnings
warnings.filterwarnings('ignore')
------------------

[0;31m---------------------------------------------------------------------------[0m
[0;31mModuleNotFoundError[0m                       Traceback (most recent call last)
Cell [0;32mIn [1], line 18[0m
[1;32m     14[0m [38;5;28;01mfrom[39;00m [38;5;21;01mitertools[39;00m [38;5;28;01mimport[39;00m chain
[1;32m     16[0m [38;5;28;01mfrom[39;00m [38;5;21;01mSyncRNG[39;00m [38;5;28;01mimport[39;00m SyncRNG
[0;32m---> 18[0m [38;5;28;01mfrom[39;00m [38;5;21;01mCTL[39;00m[38;5;21;01m.[39;00m[38;5;21;01mcausal_tree_learn[39;00m [38;5;28;01mimport[39;00m CausalTree
[1;32m     19[0m [38;5;28;01mfrom[39;00m [38;5;21;01msklearn[39;00m[38;5;21;01m.[39;00m[38;5;21;01mmodel_selection[39;00m [38;5;28;01mimport[39;00m train_test_split
[1;32m     20[0m [38;5;28;01mimport[39;00m [38;5;21;01mplotnine[39;00m [38;5;28;01mas[39;00m [38;5;21;01mp[39;00m

[0;31mModuleNotFoundError[0m: No module named 'CTL'
ModuleNotFoundError: No module named 'CTL'

